Workbook

Sheet 2023 CIAC Rates
B1: NEW CIAC RATES
B2: LISTED IN THE ORDER THEY APPEAR ON THE CIAC WORKSHEET
B4: New Description | C4: Company | D4: Rate
B5: Labor | C5: BECO | D5: 1
B6: Labor | C6: CAMB | D6: 1
B7: Labor | C7: COMM | D7: 1
B8: Craft NPT (% of Labor) | C8: BECO | D8: 0.184
B9: Craft NPT (% of Labor) | C9: CAMB | D9: 0.184
B10: Craft NPT (% of Labor) | C10: COMM | D10: 0.184
B11: Benefits & Payroll Tax (% of Labor) | C11: BECO | D11: 0.033
B12: Benefits & Payroll Tax (% of Labor) | C12: CAMB | D12: 0.033
B13: Benefits & Payroll Tax (% of Labor) | C13: COMM | D13: 0.033
B14: E&S OH (% of Labor & Outsxide Services) | C14: COMM | D14: 0.81
B15: E&S OH (% of Labor & Outsxide Services) | C15: CAMB | D15: 0.81
B16: E&S OH (% of Labor & Outsxide Services) | C16: BECO | D16: 0.81
... B34: Material Price Adjustment | C34: COMM | D34: 0

Sheet 2023 OH Rates
A1: Line Rates
A3: Labor | B3: 1 | C3: Labor
A4: NPT | B4: 0.184 | C4: Labor & OT
A5: Payroll Benefits | B5: 0.198 | C5: Labor, NPT & OT
A6: MDEC | B6: 0.06 | C6: Labor, OT, NPT, PRB & Ouside Services
A7: E&S | B7: 0.75 | C7: Labor, OT, NPT, PRB & Ouside Services
A8: AS&E | B8: 0.0075 | C8: Labor, OT, NPT, PRB, Materials, Lobby Stock Loader, Stores Loader & Ouside Services
A9: Lobby Stock | B9: 0.19 | C9: Materials
A10: Stores | B10: 0.12 | C10: Materials
A11: NSTAR Vehicles | B11: 0.212 | C11: Labor & OT
A12: AFUDC | B12: 0.0661 | C12: Fully Loaded Spending
A13: Carring Charge | B13: 0.1571 | C13: Carrying Charge
A15: Station Rates
A17: NPT | B17: 0.184 | C17: Labor & OT
A18: Payroll Benefits | B18: 0.198 | C18: Labor, NPT & OT
A19: MDEC | B19: 0.06 | C19: Labor, OT, NPT, PRB & Ouside Services
A20: E&S | B20: 0.75 | C20: Labor, OT, NPT, PRB & Ouside Services
A21: AS&E | B21: 0.0075 | C21: Labor, OT, NPT, PRB, Materials, Lobby Stock Loader, Stores Loader & Ouside Services
A22: Lobby Stock | B22: 0.19 | C22: Materials
A23: Stores | B23: 0.12 | C23: Materials
A24: NSTAR Vehicles | B24: 0.212 | C24: Labor & OT
A25: AFUDC | B25: 0.0661 | C25: Fully Loaded Spending

Sheet CIAC INPUT
A1: USE THIS WORKSHEET TO INPUT WHAT IS NORMALLY INPUT TO THE CIAC WEB APPLICATION
A2: Please DO NOT change any fields in the TEST WO tabs
A3: Input here will populate the TEST WO tabs and you will reconcile the CIAC Web Test to the TEST WO tab
A4: There may be differences due to rounding.
A6: Customer Name | B6: INPUT CUSTOMER NAME
A7: WO Description | B7: INPUT WORK ORDER DESCRIPTION
A8: WO # 1 | B8: xxxxxxxx
A9: WO # 2 | B9: xxxxxxxx
A13: Passport WO Estimate - M611 Panel | B13: WO #1 | C13: WO #2 | D13: WO #3
A14: LABOR | B14: =CABLE!C35+EQUIPMENT!C46 -> 177329.2 | C14: 0 | D14: 0
A15: MATERIALS | B15: =CABLE!C34+EQUIPMENT!C45 -> 1395747.4 | C15: 0 | D15: 0
A16: OUTSIDE SERVICES | B16: =CONDUIT!L71 -> 1015700 | C16: 0 | D16: 0
A19: Subtract: System Development, precap, etc. | B19: WO #1
A20: LABOR | B20: =B14*0.1 -> 17732.92
A21: MATERIALS | B21: =B15*0.1 -> 139574.74
A22: OUTSIDE SERVICES | B22: =B16*0.1 -> 101570
A24: Subtract Priv Prop UG Cost
A25: LABOR | B25: 0
A26: MATEIRALS | B26: 0
A27: OUTSIDE SERVICES | B27: 0
A30: Police Details | B30: 100 | C30: *INPUT HOURS AS EXPECTED TO SHOW BASED ON AGREEMENT
A31: Specific Paving not on WO | B31: 0
A32: Other Costs/Adjustment | B32: 0
A34: Credits, incl Stock Returns, Salvage, etc. | B34: 0
A36: Adj for JO Poles (From IOP) | B36: Qty | C36: Calc'd Credit
A37: NSTAR Set # of Poles | B37: 0 | C37: =-B37*400 -> 0
A38: Telco Set # of Pole | B38: 0 | C38: =+B38*400 -> 0
A39: Pole Height Premium | B39: 0 | C39: =+B39*100 -> 0
A40: Pole Credit ($ from PassPort WO) | B40: 0 | C40: =-B40*1435 -> 0
A41: wire Credit ($ from Passport WO) | B41: 0 | C41: =-B41*1026 -> 0
A43: Private Property Overhead Costs
A44: Company Labor | B44: 0
A45: Stk/Direc Chrg Mtl | B45: 0
A46: Out Srv/Misc Exp | B46: 0
A49: Net Revenue | B49: 800000 | C49: Input based on Passport revenue in attributes
A51: Add: Customer Supplied Cost (from CSCS) | B51: 0 | C51: *Please input CSCS amount from Web Application
A52: Customer supplied Conduit URD Material | B52: 0 | C52: no changes were made to the CSCS
A54: Subtract Design Deposit | B54: 0

Sheet MOCK CIAC
C1: Passport Data
A2: BOSTON EDISON | C2: Auto input from INPUT tab
C3: Table Rate
A6: Work order
A7: Current Job | B7: =+'CIAC INPUT'!B8 -> xxxxxxxx
A8: Cust Name | B8: =+'CIAC INPUT'!B6 -> INPUT CUSTOMER NAME
A9: WO Desc | B9: =+'CIAC INPUT'!B7 -> INPUT WORK ORDER DESCRIPTION
C11: Co Labor | D11: Stock Mats | E11: Outside Srv | F11: Total Cost
A12: Current WO # | B12: =+'CIAC INPUT'!B8 -> xxxxxxxx | C12: =+'CIAC INPUT'!B14 -> 177329.2 | D12: =+'CIAC INPUT'!B15 -> 1395747.4 | E12: =+'CIAC INPUT'!B16 -> 1015700 | F12: =SUM(C12:E12) -> 2588776.5
A13: Related WO # | B13: =+'CIAC INPUT'!B9 -> xxxxxxxx | C13: =+'CIAC INPUT'!C14 -> 0 | D13: =+'CIAC INPUT'!C15 -> 0 | E13: =+'CIAC INPUT'!C16 -> 0
A14: Related WO # | B14: xxxxxxxx | C14: =+'CIAC INPUT'!D14 -> 0 | D14: =+'CIAC INPUT'!D15 -> 0 | E14: =+'CIAC INPUT'!D16 -> 0 | F14: =SUM(C14:E14) -> 0
C15: =SUM(C12:C14) -> 177329.2 | D15: =SUM(D12:D14) -> 1395747.4 | E15: =SUM(E12:E14) -> 1015700
A16: Subtract: System Development, precap, etc. | C16: =+'CIAC INPUT'!B20 -> 17732.92 | D16: =+'CIAC INPUT'!B21 -> 139574.74 | E16: =+'CIAC INPUT'!B22 -> 101570
A17: Subtotal: Work Order Costs from Passport less System Dev | C17: =+C15-C16 -> 159596.28 | D17: =+D15-D16 -> 1256172.6 | E17: =+E15-E16 -> 914130
A19: Add: Material Price Adjustment (MPA) | B19: =+'2023 CIAC Rates'!D33 -> 0 | D19: =+B19*D17 -> 0
A20: Subtotal: Material Costs Less System Development Plus MPA | C20: =SUM(C17:C19) -> 159596.28 | D20: =SUM(D17:D19) -> 1256172.6 | E20: =SUM(E17:E19) -> 914130 | F20: =SUM(C20:E20) -> 2329898.9
A21: Test and Carrying Charge
A23: Subtract Priv Prop UG Cost (from Tasks on Passport WO, Cust wil own) | C23: =+'CIAC INPUT'!B25 -> 0 | D23: =+'CIAC INPUT'!B26 -> 0 | E23: =+'CIAC INPUT'!B27 -> 0
A24: Add: MPA | B24: =+'2023 CIAC Rates'!D34 -> 0 | D24: =+B24*D23 -> 0
A25: Subtotal: Private Property UG Material Cost + MPA | D25: =+D24+D23 -> 0
A26: Subtotal: Net Labor, Material, Srv/Misc Costs for OH, Revenue | C26: =+C20-C23 -> 159596.28 | D26: =+D20-D25 -> 1256172.6 | E26: =+E20-E23 -> 914130 | F26: =SUM(C26:E26) -> 2329898.9
A27: test and Carrying Charge
A30: Labor | D30: ='2023 CIAC Rates'!D5 -> 1 | E30: =+C26 -> 159596.28
A34: Craft NPT (% of labor) | D34: ='2023 CIAC Rates'!D8 -> 0.184 | F34: =+D34*E30 -> 29365.716
A38: Benefits & Payroll Tax (% of labor) | D38: ='2023 CIAC Rates'!D11 -> 0.033 | F38: =+D38*(E30+F34) -> 6235.7459
A42: E&S OH (% of Labor & Outside Services) | D42: ='2023 CIAC Rates'!D14 -> 0.81 | F42: =+D42*(E30+F34+F38+E26) -> 898555.47
A46: AS&E OH (% Labor, Labor OH, E&S, Lobby, Stores, Vehicles) | D46: ='2023 CIAC Rates'!D17 -> 0.008 | F46: =+D46*(E30+F34+F38+F42+F50+F54+F62+D26+E26) -> 29738.463
A50: Lobby Stock (% of Stock Material & MPA) | D50: ='2023 CIAC Rates'!D20 -> 0.19 | F50: =+D50*D26 -> 238672.8
A54: Stores OH (% of Stock Materials & MPA) | D54: ='2023 CIAC Rates'!D23 -> 0.12 | F54: =+D54*D26 -> 150740.71
A58: Police Details: Charged in WO | D58: Police detail:N | F58: =+'CIAC INPUT'!B30*46 -> 4600
A59: Specific Paving not on WO | F59: =+'CIAC INPUT'!B31 -> 0
A60: Other Costs/Adjustment | F60: =+'CIAC INPUT'!B32 -> 0
A62: Vehicle (% of Labor) | D62: ='2023 CIAC Rates'!D26 -> 0.4 | F62: =+D62*E30 -> 63838.512
A65: Credits, incl. stock returns, salvage, etc. | D65: =((+'CIAC INPUT'!B34+('CIAC INPUT'!B34*'2023 CIAC Rates'!D32)+('CIAC INPUT'!B34*'2023 CIAC Rates'!D20)-('CIAC INPUT'!B34*'2023 CIAC Rates'!D25))*-1) -> 0 | F65: =+D65 -> 0
A67: Subtotal: Work Order Cost (with all overheads) | F67: =+F26+F34+F38+F42+F46+F50+F54+F58+F59+F60+F62+F65 -> 3751646.3
B69: Enter Qty | C69: Enter Unit $
A71: Adj for JO Poles NSTAR Set # of Poles | B71: =+'CIAC INPUT'!B37 -> 0 | C71: 400 | F71: =+'CIAC INPUT'!C37 -> 0
A72: TELCO Set # of Poles | B72: =+'CIAC INPUT'!B38 -> 0 | C72: 400 | F72: =+'CIAC INPUT'!C38 -> 0 | G72: 0
A73: Pole Height Premium NSTAR Set # of Poles | B73: =+'CIAC INPUT'!B39 -> 0 | C73: 100 | F73: =+'CIAC INPUT'!C39 -> 0
A74: Pole Credit ($ from PassPort WO # of Poles (Max 1) | B74: =+'CIAC INPUT'!B40 -> 0 | C74: 1435 | F74: =+'CIAC INPUT'!C40 -> 0
...

Sheet FULL LOADED COST
A1: Indirect/Overhead Calculation Template
A5: Line Work | G5: Station Work
B7: 2025 | E7: Total | H7: Year 1 | K7: Total | M7: Project Total
A8: Labor | B8: =CABLE!C35+EQUIPMENT!C46 -> 177329.2 | E8: =SUM(B8:D8) -> 177329.2 | G8: Labor | H8: 0 | K8: =SUM(H8:J8) -> 0 | M8: =E8+K8 -> 177329.2
A9: Labor | B9: =B8 -> 177329.2 | C9: =C8 -> 0 | D9: =D8 -> 0 | E9: =E8 -> 177329.2 | G9: Labor | H9: =H8 -> 0 | I9: =I8 -> 0 | J9: =J8 -> 0 | K9: =K8 -> 0 | M9: =E9+K9 -> 177329.2
A10: Materials | B10: =CABLE!C34+EQUIPMENT!C45 -> 1395747.4 | E10: =SUM(B10:D10) -> 1395747.4 | G10: Materials | H10: 0 | K10: =SUM(H10:J10) -> 0 | M10: =E10+K10 -> 1395747.4
A11: Outside Services | B11: =CONDUIT!L71 -> 1015700 | E11: =SUM(B11:D11) -> 1015700 | G11: Outside Services | H11: 0 | K11: =SUM(H11:J11) -> 0 | M11: =E11+K11 -> 1015700
A12: Other (Salvage Credit) | B12: 0 | E12: =SUM(B12:D12) -> 0 | G12: Other | H12: 0 | K12: =SUM(H12:J12) -> 0 | M12: =E12+K12 -> 0
A13: Total Direct Costs | B13: =SUM(B9:B12) -> 2588776.5 | C13: =SUM(C9:C12) -> 0 | D13: =SUM(D9:D12) -> 0 | E13: =SUM(E9:E12) -> 2588776.5 | G13: Total Direct Costs | H13: =SUM(H9:H12) -> 0 | I13: =SUM(I9:I12) -> 0 | J13: =SUM(J9:J12) -> 0 | K13: =SUM(K9:K12) -> 0 | M13: =SUM(M9:M12) -> 2588776.5
A15: Cust Contribution (negative number) | B15: 0 | E15: =SUM(B15:D15) -> 0 | G15: Customer Contribution | K15: =SUM(H15:J15) -> 0 | M15: =E15+K15 -> 0
A17: NPT | B17: =+B9*'2023 OH Rates'!$B$4 -> 32628.573 | C17: =+C9*'2023 OH Rates'!$B$4 -> 0 | D17: =+D9*'2023 OH Rates'!$B$4 -> 0 | E17: =SUM(B17:D17) -> 32628.573 | G17: NPT | H17: =+H9*'2023 OH Rates'!$B$17 -> 0 | I17: =+I9*'2023 OH Rates'!$B$17 -> 0 | J17: =+J9*'2023 OH Rates'!$B$17 -> 0 | K17: =SUM(H17:J17) -> 0 | M17: =E17+K17 -> 32628.573
A18: Payroll Benefits | B18: =+'2023 OH Rates'!$B$5*(B17+B9) -> 41571.639 | C18: =+'2023 OH Rates'!$B$5*(C17+C9) -> 0 | D18: =+'2023 OH Rates'!$B$5*(D17+D9) -> 0 | E18: =SUM(B18:D18) -> 41571.639 | G18: Payroll Benefits | H18: =+'2023 OH Rates'!$B$18*(H17+H9) -> 0 | I18: =+'2023 OH Rates'!$B$18*(I17+I9) -> 0 | J18: =+'2023 OH Rates'!$B$18*(J17+J9) -> 0 | K18: =SUM(H18:J18) -> 0 | M18: =E18+K18 -> 41571.639
A19: MDEC | B19: =+'2023 OH Rates'!$B$6*(B9+B11+B17+B18) -> 76033.765 | C19: =+'2023 OH Rates'!$B$6*(C9+C11+C17+C18) -> 0 | D19: =+'2023 OH Rates'!$B$6*(D9+D11+D17+D18) -> 0 | E19: =SUM(B19:D19) -> 76033.765 | G19: MDEC | H19: =+'2023 OH Rates'!$B$19*(H9+H11+H17+H18) -> 0 | I19: =+'2023 OH Rates'!$B$19*(I9+I11+I17+I18) -> 0 | J19: =+'2023 OH Rates'!$B$19*(J9+J11+J17+J18) -> 0 | K19: =SUM(H19:J19) -> 0 | M19: =E19+K19 -> 76033.765
A20: E&S | B20: =+'2023 OH Rates'!$B$7*(B9+B11+B17+B18) -> 950422.06 | C20: =+'2023 OH Rates'!$B$7*(C9+C11+C17+C18) -> 0 | D20: =+'2023 OH Rates'!$B$7*(D9+D11+D17+D18) -> 0 | E20: =SUM(B20:D20) -> 950422.06 | G20: E&S | H20: =+'2023 OH Rates'!$B$20*(H9+H11+H17+H18) -> 0 | I20: =+'2023 OH Rates'!$B$20*(I9+I11+I17+I18) -> 0 | J20: =+'2023 OH Rates'!$B$20*(J9+J11+J17+J18) -> 0 | K20: =SUM(H20:J20) -> 0 | M20: =E20+K20 -> 950422.06
A21: AS&E | B21: =+'2023 OH Rates'!$B$8*(B13+B17+B18+B22+B23) -> 23217.438 | C21: =+'2023 OH Rates'!$B$8*(C13+C17+C18+C22+C23) -> 0 | D21: =+'2023 OH Rates'!$B$8*(D13+D17+D18+D22+D23) -> 0 | E21: =SUM(B21:D21) -> 23217.438 | G21: AS&E | H21: =+'2023 OH Rates'!$B$8*(H13+H17+H18+H22+H23) -> 0 | I21: =+'2023 OH Rates'!$B$8*(I13+I17+I18+I22+I23) -> 0 | J21: =+'2023 OH Rates'!$B$8*(J13+J17+J18+J22+J23) -> 0 | K21: =SUM(H21:J21) -> 0 | M21: =E21+K21 -> 23217.438
A22: Lobby Stock | B22: =+'2023 OH Rates'!$B$9*B10 -> 265192 | C22: =+'2023 OH Rates'!$B$9*C10 -> 0 | D22: =+'2023 OH Rates'!$B$9*D10 -> 0 | E22: =SUM(B22:D22) -> 265192 | G22: Lobby Stock | H22: =+'2023 OH Rates'!$B$22*H10 -> 0 | I22: =+'2023 OH Rates'!$B$22*I10 -> 0 | J22: =+'2023 OH Rates'!$B$22*J10 -> 0 | K22: =SUM(H22:J22) -> 0 | M22: =E22+K22 -> 265192
A23: Stores | B23: =+'2023 OH Rates'!$B$10*B10 -> 167489.68 | C23: =+'2023 OH Rates'!$B$10*C10 -> 0 | D23: =+'2023 OH Rates'!$B$10*D10 -> 0 | E23: =SUM(B23:D23) -> 167489.68 | G23: Stores | H23: =+'2023 OH Rates'!$B$23*H10 -> 0 | I23: =+'2023 OH Rates'!$B$23*I10 -> 0 | J23: =+'2023 OH Rates'!$B$23*J10 -> 0 | K23: =SUM(H23:J23) -> 0 | M23: =E23+K23 -> 167489.68
A24: NSTAR Vehicles | B24: =+'2023 OH Rates'!$B$11*B9 -> 37593.79 | C24: =+'2023 OH Rates'!$B$11*C9 -> 0 | D24: =+'2023 OH Rates'!$B$11*D9 -> 0 | E24: =SUM(B24:D24) -> 37593.79 | G24: NSTAR Vehicles | H24: =+'2023 OH Rates'!$B$24*H9 -> 0 | I24: =+'2023 OH Rates'!$B$24*I9 -> 0 | J24: =+'2023 OH Rates'!$B$24*J9 -> 0 | K24: =SUM(H24:J24) -> 0 | M24: =E24+K24 -> 37593.79
A25: Total Indirect Costs | B25: =SUM(B17:B24) -> 1594148.9 | C25: =SUM(C17:C24) -> 0 | D25: =SUM(D17:D24) -> 0 | E25: =SUM(E17:E24) -> 1594148.9 | G25: Total Indirect Costs | H25: =SUM(H17:H24) -> 0 | I25: =SUM(I17:I24) -> 0 | J25: =SUM(J17:J24) -> 0 | K25: =SUM(K17:K24) -> 0 | M25: =SUM(M17:M24) -> 1594148.9
A27: AFUDC | B27: =IF($M27=0,0,(B13/$M13*$M27)) -> 276491.38 | C27: =IF($M27=0,0,(C13/$M13*$M27)) -> 0 | D27: =IF($M27=0,0,(D13/$M13*$M27)) -> 0 | E27: =SUM(B27:D27) -> 276491.38 | G27: AFUDC | H27: =IF($M27=0,0,(H13/$M13*$M27)) -> 0 | I27: =IF($M27=0,0,(I13/$M13*$M27)) -> 0 | J27: =IF($M27=0,0,(J13/$M13*$M27)) -> 0 | K27: =SUM(H27:J27) -> 0 | M27: =IF('2023 OH Rates'!B12*(M13+M25+M15)<0,0,'2023 OH Rates'!B12*(M13+M25+M15)) -> 276491.38
A29: Project Costs Summary
A30: Capital Costs | B30: 2025 | E30: Total
A31: Direct Capital Costs
A32: Internal Labor and Construction Equipment | B32: =B9+H9 -> 177329.2 | C32: =C9+I9 -> 0 | D32: =D9+J9 -> 0 | E32: =SUM(B32:D32) -> 177329.2
A33: Outside Services | B33: =B11+H11 -> 1015700 | C33: =C11+I11 -> 0 | D33: =D11+J11 -> 0 | E33: =SUM(B33:D33) -> 1015700
A34: Materials | B34: =B10+H10 -> 1395747.4 | C34: =C10+I10 -> 0 | D34: =D10+J10 -> 0 | E34: =SUM(B34:D34) -> 1395747.4
A35: Removals | B35: 0 | C35: 0 | D35: 0 | E35: =SUM(B35:D35) -> 0
A36: Risk and Contingency (0%) | B36: 0 | C36: 0 | D36: 0 | E36: =SUM(B36:D36) -> 0
A37: Other | B37: =B12+H12 -> 0 | C37: =C12+I12 -> 0 | D37: =D12+J12 -> 0 | E37: =SUM(B37:D37) -> 0
A38: Subtotal | B38: =SUM(B32:B37) -> 2588776.5 | C38: =SUM(C32:C37) -> 0 | D38: =SUM(D32:D37) -> 0 | E38: =SUM(E32:E37) -> 2588776.5
A39: Indirect Capital Costs
A40: Indirect/Overhead (including benefits) | B40: =B25+H25 -> 1594148.9 | C40: =C25+I25 -> 0 | D40: =D25+J25 -> 0 | E40: =SUM(B40:D40) -> 1594148.9
A41: Capitlized interest or AFDUC, if any | B41: =B27+H27 -> 276491.38 | C41: =C27+I27 -> 0 | D41: =D27+J27 -> 0 | E41: =SUM(B41:D41) -> 276491.38
A42: Subtotal | B42: =SUM(B40:B41) -> 1870640.3 | C42: =SUM(C40:C41) -> 0 | D42: =SUM(D40:D41) -> 0 | E42: =SUM(E40:E41) -> 1870640.3
A43: Total Capital Costs | B43: =B38+B42 -> 4459416.9 | C43: =C38+C42 -> 0 | D43: =D38+D42 -> 0 | E43: =SUM(B43:D43) -> 4459416.9 | G43: **PAF required if Total Capital Costs exceed $500k
A44: Total Customer Contribution | B44: =B15 -> 0 | C44: 0 | D44: 0 | E44: =SUM(B44:D44) -> 0
A45: Total Capital Project Costs | B45: =B43+B44 -> 4459416.9 | C45: =C43+C44 -> 0 | D45: =D43+D44 -> 0 | E45: =SUM(B45:D45) -> 4459416.9

Sheet CABLE
A1: Material | B1: Item # | C1: Cost/unit | D1: Replacement? | E1: # Sections | F1: Distance | H1: Hours | I1: Cost (30ft of slack per section included) | J1: Total Cable with slack
A2: SECONDARY
A3: #4 600V | B3: 500001 | C3: 0.851 | H3: =E3*16 -> 0 | I3: =C3*(F3+(E3*30)) -> 0 | J3: =F3+(E3*30) -> 0
A4: 1/0 600V | B4: 500004 | C4: 1.86 | H4: =E4*16 -> 0 | I4: =C4*(F4+(E4*30)) -> 0 | J4: =F4+(E4*30) -> 0
A5: 4/0 600V | B5: 500033 | C5: 3.882 | H5: =E5*16 -> 0 | I5: =C5*(F5+(E5*30)) -> 0 | J5: =F5+(E5*30) -> 0
A6: 350 600V | B6: 500008 | C6: 6.072 | H6: =E6*16 -> 0 | I6: =C6*(F6+(E6*30)) -> 0 | J6: =F6+(E6*30) -> 0
A7: 500 600V | B7: 500030 | C7: 9.717 | H7: =E7*16 -> 0 | I7: =C7*(F7+(E7*30)) -> 0 | J7: =F7+(E7*30) -> 0
A8: 7-4/0 600V | B8: 574050 | C8: 46.87 | H8: =E8*16 -> 0 | I8: =C8*(F8+(E8*30)) -> 0 | J8: =F8+(E8*30) -> 0
I9: =C9*(F9+(E9*30)) -> 0
A10: PRIMARY | I10: =C10*(F10+(E10*30)) -> 0
A11: #2CU 15kV | B11: 574158 | C11: 11.0558 | H11: =E11*16 -> 0 | I11: =C11*(F11+(E11*30)) -> 0 | J11: =F11+(E11*30) -> 0
A12: #1 AL 15kV | B12: 574156 | C12: 5.239 | H12: =E12*16 -> 0 | I12: =C12*(F12+(E12*30)) -> 0 | J12: =F12+(E12*30) -> 0
A13: 4/0 AL 15kV | B13: 580480 | C13: 8.86 | H13: =E13*16 -> 0 | I13: =C13*(F13+(E13*30)) -> 0 | J13: =F13+(E13*30) -> 0
A14: 3-250 FS 15kV | B14: 574053 | C14: 18.62 | D14: 514037 | H14: =E14*16 -> 0 | I14: =C14*(F14+(E14*30)) -> 0 | J14: =F14+(E14*30) -> 0
A15: 3-500 FS 15kV | B15: 574055 | C15: 39.65 | E15: 0 | F15: 0 | H15: =E15*16 -> 0 | I15: =C15*(F15+(E15*30)) -> 0 | J15: =F15+(E15*30) -> 0
A16: 3-700 FS 15kV | B16: 574163 | C16: 74.67 | E16: 47 | F16: 16395 | H16: =E16*16 -> 752 | I16: =C16*(F16+(E16*30)) -> 1329499.4 | J16: =F16+(E16*30) -> 17805
A17: 3-1000 FS 15kV | B17: 579221 | C17: 52.54 | E17: 0 | F17: 0 | H17: =E17*16 -> 0 | I17: =C17*(F17+(E17*30)) -> 0 | J17: =F17+(E17*30) -> 0
A19: PRELIM SPLICING | E19: # MHs
A20: Straight joint | C20: 864 | E20: 73 | I20: =C20*E20 -> 63072
A21: Multiple joint | C21: 1588 | I21: =C21*E21 -> 0
A23: PERMIT SPLICING | E23: # MHs
A24: Straight joint | C24: 864 | I24: =C24*E24 -> 0
A25: Multiple joint | C25: 1588 | E25: 2 | I25: =C25*E25 -> 3176
A27: Labor | C27: Hours or units | D27: Cost/unit | E27: Cost
A29: Cable (hours) | C29: =SUM(H3:H17) -> 752 | D29: 55.28 | E29: =C29*D29 -> 41570.56
A30: Prelim Splice (hours) | C30: =E20*16+E21*24+E24*24+E25*36 -> 1240 | D30: 66 | E30: =(C30-((E24*24)+(E25*36)))*D30 -> 77088
A31: Prelim Look up (hours) | C31: =IF(SUM(E3:E17)=0,0,(SUM(E3:E17)+1)*4) -> 192 | D31: 69.4 | E31: =C31*D31 -> 13324.8
A32: Permit (MH units) | C32: =SUM(E24:E25) -> 2 | D32: 4940 | E32: =C32*D32 -> 9880
A34: Material cost | C34: =SUM(I3:I17)+SUM(I20:I21)+SUM(I24:I25) -> 1395747.4
A35: Labor cost | C35: =SUM(E29:E32)*(1+D35) -> 177329.2 | D35: 0.25 | E35: Labor adder
A36: Total cost | C36: =C34+C35 -> 1573076.6

Sheet CONDUIT
B2: Item of Work | D2: Size | E2: Condition | F2: Units | H2: Quantity | J2: Quote | L2: 2018 RATES | M2: Quote | N2: 2018
B4: Single Pipe Svs (SPS) by NSTAR | C4: Schedule 40 | D4: All | E4: Minimum 50 Lin Ft. | F4: Lin Ft | I4: * | J4: =SUM(H4*M4) -> 0 | L4: =SUM(H4*N4) -> 0 | M4: 106 | N4: 44
B5: Paving Allowance for SPS | C5: Trench L x W | D5: All | E5: Minimum 150 Sq Ft | F5: Sq Ft | I5: * | J5: =SUM(H5*M5) -> 0 | L5: =SUM(H5*N5) -> 0 | M5: 60 | N5: 25
B7: (2) PVC Type EB in Concrete | D7: All | E7: Under Street Paving 0"-12" | F7: Lin Ft | J7: =SUM(H7*M7) -> 0 | L7: =SUM(H7*N7) -> 0 | M7: 264 | N7: 70
B8: (3) PVC Type EB in Concrete | D8: All | E8: Under Street Paving 0"-12" | F8: Lin Ft | J8: =SUM(H8*M8) -> 0 | L8: =SUM(H8*N8) -> 0 | M8: 248 | N8: 65
B9: (4) PVC Type EB in Concrete | D9: All | E9: Under Street Paving 0"-12" | F9: Lin Ft | J9: =SUM(H9*M9) -> 0 | L9: =SUM(H9*N9) -> 0 | M9: 308 | N9: 70
B10: (6) PVC Type EB in Concrete | D10: All | E10: Under Street Paving 0"-12" | F10: Lin Ft | H10: 1270 | J10: =SUM(H10*M10) -> 419100 | L10: =SUM(H10*N10) -> 107950 | M10: 330 | N10: 85
B11: (8 & 9) PVC Type EB in Concrete | D11: All | E11: Under Street Paving 0"-12" | F11: Lin Ft | J11: =SUM(H11*M11) -> 0 | L11: =SUM(H11*N11) -> 0 | M11: 407 | N11: 145
B12: (12) PVC Type EB in Concrete | D12: All | E12: Under Street Paving 0"-12" | F12: Lin Ft | J12: =SUM(H12*M12) -> 0 | L12: =SUM(H12*N12) -> 0 | M12: 451 | N12: 175
B13: Precast Manholes | D13: 4 x 4 x 6 | E13: PC MH 4' x 4' x 6' | F13: Each | H13: 0 | J13: =SUM(H13*M13) -> 0 | L13: =SUM(H13*N13) -> 0 | M13: 25300 | N13: 6500
B14: Precast Manholes | D14: 4 x 6 x 8 | E14: PC MH 4' x 6' x 8' | F14: Each | J14: =SUM(H14*M14) -> 0 | L14: =SUM(H14*N14) -> 0 | M14: 31477 | N14: 10500
B15: Precast Manholes | D15: 6 x 10 x 8 | E15: PC MH 6' x 10' x 8' | F15: Each | H15: 0 | J15: =SUM(H15*M15) -> 0 | L15: =SUM(H15*N15) -> 0 | M15: 49610 | N15: 20000
B16: Precast Manholes | D16: 6 x 10 x 10 | E16: PC MH 6' x 10' x 10' | F16: Each | H16: 0 | J16: =SUM(H16*M16) -> 0 | L16: =SUM(H16*N16) -> 0 | M16: 52250 | N16: 23000
B17: Precast Manholes | D17: HA-300 | E17: PC HA-300 | F17: Each | H17: 3 | J17: =SUM(H17*M17) -> 191400 | L17: =SUM(H17*N17) -> 102000 | M17: 63800 | N17: 34000
B18: Precast Manholes | D18: HA-400 | E18: PC HA-400 | F18: Each | H18: 0 | J18: =SUM(H18*M18) -> 0 | L18: =SUM(H18*N18) -> 0 | M18: 76819 | N18: 50000
B19: Cast-In-Place Manholes | D19: 4 x 4 x 6 | E19: CIP MH 4' x 4' x 6' | F19: Each | H19: 0 | J19: =SUM(H19*M19) -> 0 | L19: =SUM(H19*N19) -> 0 | M19: 25300 | N19: 11500
B20: Cast-In-Place Manholes | D20: 4 x 6 x 8 | E20: CIP MH 4' x 6' x 8' | F20: Each | H20: 0 | J20: =SUM(H20*M20) -> 0 | L20: =SUM(H20*N20) -> 0 | M20: 31477 | N20: 23100
B21: Cast-In-Place Manholes | D21: 6 x 10 x 8 | E21: CIP MH 6' x 10' x 8' | F21: Each | H21: 0 | J21: =SUM(H21*M21) -> 0 | L21: =SUM(H21*N21) -> 0 | M21: 49610 | N21: 27500
B22: Cast-In-Place Manholes | D22: 6 x 10 x 10 | E22: CIP MH 6' x 10' x 10' | F22: Each | H22: 0 | J22: =SUM(H22*M22) -> 0 | L22: =SUM(H22*N22) -> 0 | M22: 52250 | N22: 27500
B23: Cast-In-Place Manholes | D23: HA-300 | E23: CIP MH HA-300 | F23: Each | H23: 0 | J23: =SUM(H23*M23) -> 0 | L23: =SUM(H23*N23) -> 0 | M23: 63800 | N23: 40700
B24: Cast-In-Place Manholes | D24: HA-400 | E24: CIP MH HA-400 | F24: Each | H24: 0 | J24: =SUM(H24*M24) -> 0 | L24: =SUM(H24*N24) -> 0 | M24: 76819 | N24: 50000
B25: ReRoof Manhole | D25: 4 x 6 | E25: ReRoof MH 4' x 6' | F25: Each | H25: 0 | J25: =SUM(H25*M25) -> 0 | L25: =SUM(H25*N25) -> 0 | M25: 27600 | N25: 11500
B26: ReRoof Manhole | D26: 5 x 7 | E26: ReRoof 5' x 7' | F26: Each | H26: 0 | J26: =SUM(H26*M26) -> 0 | L26: =SUM(H26*N26) -> 0 | M26: 28800 | N26: 12000
... B34: Rebuild Manholes | D34: 6 x 10 x 8 | E34: MH 6' x 10' x 8' | F34: Each | H34: 0 | J34: =SUM(H34*M34) -> 0 | L34: =SUM(H34*N34) -> 0 | M34: 165600 | N34: 69000
B35: Rebuild Manholes | D35: 6 x 10 x 10 | E35: MH 6' x 10' x 10' | F35: Each | J35: =SUM(H35*M35) -> 0 | L35: =SUM(H35*N35) -> 0 | M35: 165600 | N35: 69000
B36: Rebuild Manholes | D36: HA-300 | E36: MH HA-300 | F36: Each | H36: 0 | J36: =SUM(H36*M36) -> 0 | L36: =SUM(H36*N36) -> 0 | M36: 176400 | N36: 98000
B37: Rebuild Manholes | D37: HA-400 | E37: MH HA-400 | F37: Each | H37: 0 | J37: =SUM(H37*M37) -> 0 | L37: =SUM(H37*N37) -> 0 | M37: 221400 | N37: 123000
B38: Sidewalk Restoration | D38: Various | E38: Remove/Replace | F38: Sq Ft | H38: 0 | J38: =SUM(H38*M38) -> 0 | L38: =SUM(H38*N38) -> 0 | M38: 156 | N38: 65
B39: Restore Handicapped Ramps | D39: Standard | E39: Remove/Replace for Compliance | F39: Pair | H39: 0 | J39: =SUM(H39*M39) -> 0 | L39: =SUM(H39*N39) -> 0 | M39: =N39*1.2 -> 13200 | N39: 11000
B40: Daily Crew | D40: Typical | E40: Stock & Labor Crew | F40: Day | H40: 0 | J40: =SUM(H40*M40) -> 0 | L40: =SUM(H40*N40) -> 0 | M40: 7590 | N40: 2675
B41: Per Project Allowance to Excavate Ledge | D41: Various | E41: Excavate Ledge | F41: Cu Yds | G41: =SUM((((H7+H8+H9+H10+H11+H12)*3)/27)+((((5*7)*(H13+H14+H19+H20)))/27)+((((7*11)*(H15+H21+H16+H22)))/27)+((((8*14)*(H17+H23+H18+H24+H31)))/27))*0.1 -> 15.355556 | H41: =G41 -> 15.355556 | J41: =G41*M41 -> 12668.333 | L41: =SUM(H41*N41) -> 6910 | M41: 825 | N41: 450
E43: Install Control Density Fill (90pcf) | F43: Cu Yds | H43: 0 | I43: * | J43: =SUM(H43*M43) -> 0 | L43: =SUM(H43*N43) -> 0 | M43: 198 | N43: 115
E44: Disposal --- Asphalt, Brick & Concrete | F44: Tons | H44: 0 | I44: * | J44: =SUM(H44*M44) -> 0 | L44: =SUM(H44*N44) -> 0 | M44: 54 | N44: =(24*1.5) -> 36
E45: Disposal --- Soil to Lined Landfill | F45: Tons | H45: 0 | I45: * | J45: =SUM(H45*M45) -> 0 | L45: =SUM(H45*N45) -> 0 | M45: 110 | N45: =(60*1.5) -> 90
E46: Disposal --- Soil to Unlined Landfill | F46: Tons | H46: 0 | I46: * | J46: =SUM(H46*M46) -> 0 | L46: =SUM(H46*N46) -> 0 | M46: =N46*1.2 -> 90 | N46: =(50*1.5) -> 75
J49: =SUM(J4:J46) -> 623168.33 | L49: =SUM(J4:J46) -> 623168.33
B51: Variables Effecting Schedule & Costs | E51: Summary | F51: Typical* | H51: Quote | J51: Suburb | L51: Quote
B53: Paving and/or SPOF | C53: 0 | D53: (Note 1) | E53: Value from Unit Price Estimate | J53: =+J49 -> 623168.33 | L53: =+L49 -> 623168.33
B55: ADA/ABB Compliance | C55: 0 | D55: (Note 2) | E55: Police Details (excluding *) | F55: 0.1 | G55: =SUM((H7+H8+H9+H10+H11+H12)/75+(H13+H14+H15+H16+H17+H18)*4+(H19+H20+H21+H22+H23+H24)*18+(H25+H26+H27+H28+H29)*3+(H30/16)+(H31)*20+(H32+H33+H34+H35+H36+H37)*22+(H38)/300+(H39)*6+(H40)*1+(H41)/3)*350 -> 11918.148 | H55: 0.25 | J55: =G55*1.1 -> 13109.963 | L55: =G55*1.25 -> 14897.685
B57: Ledge Profile from Municipality | C57: 0 | D57: (Note 3) | E57: Subtotal | J57: =SUM(J53:J55) -> 636278.3 | L57: =SUM(L53:L55) -> 638066.02
...

Sheet EQUIPMENT
B1: EQUIPMENT | C1: LABOR(HRs) | D1: MATERIAL | E1: QUANTITY | F1: LABOR COST | G1: TOTAL COST | H1: TOTAL LABOR
A4: Item # | B4: Overhead Equipment
A6: 586850+574496 | B6: ASU 15kV 600A | C6: 8 | D6: 30225 | F6: =60*C6*E6 -> 0 | G6: =D6*E6 -> 0 | H6: =C6*E6 -> 0
A7: 586786+584353 | B7: Nova Recloser | C7: 16 | D7: 33998 | F7: =60*C7*E7 -> 0 | G7: =D7*E7 -> 0 | H7: =C7*E7 -> 0
A8: 600894 | B8: Trip Savers up to 100k (each) | C8: 6 | D8: 4198.86 | F8: =60*C8*E8 -> 0 | G8: =D8*E8 -> 0 | H8: =C8*E8 -> 0
A9: 576259 | B9: Fused Cut Out up to 80k (each) | C9: 2 | D9: 70.48 | F9: =60*C9*E9 -> 0 | G9: =D9*E9 -> 0 | H9: =C9*E9 -> 0
A10: 579254 | B10: Primary Riser | C10: 8 | D10: 268.58 | F10: =60*C10*E10 -> 0 | G10: =D10*E10 -> 0 | H10: =C10*E10 -> 0
A11: 566944 | B11: 45' Class 2 Pole | C11: 12 | D11: 490.78 | F11: =60*C11*E11 -> 0 | G11: =D11*E11 -> 0 | H11: =C11*E11 -> 0
B12: Install Open Wire - per phase/per section | C12: 1 | D12: 100 | G12: =D12*E12 -> 0 | H12: =C12*E12 -> 0
B13: Frame 3ph pole | C13: 3 | D13: 200 | G13: =D13*E13 -> 0 | H13: =C13*E13 -> 0
B14: Transfer Primary | C14: 12 | D14: 100 | G14: =D14*E14 -> 0 | H14: =C14*E14 -> 0
A15: 583821 | B15: 25 kVA OH XFMR | C15: 6 | D15: 2361 | F15: =60*C15*E15 -> 0 | G15: =D15*E15 -> 0 | H15: =C15*E15 -> 0
A16: 573073 | B16: 50 kVA OH XFMR | C16: 6 | D16: 1682 | F16: =60*C16*E16 -> 0 | G16: =D16*E16 -> 0 | H16: =C16*E16 -> 0
A17: 573080 | B17: 100 kVA OH XFMR | C17: 6 | D17: 2994 | F17: =60*C17*E17 -> 0 | G17: =D17*E17 -> 0 | H17: =C17*E17 -> 0
B18: Primary Metering Cluster | C18: 8 | D18: 9240 | F18: =60*C18*E18 -> 0 | G18: =D18*E18 -> 0 | H18: =C18*E18 -> 0
A19: 573081 | B19: Step Down XFMR 167kVA | C19: 10 | D19: 5230 | F19: =60*C19*E19 -> 0 | G19: =D19*E19 -> 0 | H19: =C19*E19 -> 0
B21: Padmount Equipment
A23: 576173 | B23: 50 kVA Padmount XFMR (1Ph) | C23: 6 | D23: 2986.02 | F23: =60*C23*E23 -> 0 | G23: =D23*E23 -> 0 | H23: =C23*E23 -> 0
A24: 576239 | B24: 100 kVA Padmount XFMR (1Ph) | C24: 6 | D24: 4215 | F24: =60*C24*E24 -> 0 | G24: =D24*E24 -> 0 | H24: =C24*E24 -> 0
A25: 579632 | B25: 167 kVA Padmount XFMR (1Ph) | C25: 6 | D25: 4829 | F25: =60*C25*E25 -> 0 | G25: =D25*E25 -> 0 | H25: =C25*E25 -> 0
A26: 572991 | B26: 150 kVA Padmount XFMR | C26: 9 | D26: 10694 | F26: =60*C26*E26 -> 0 | G26: =D26*E26 -> 0 | H26: =C26*E26 -> 0
A27: 572994 | B27: 300 kVA Padmount XFMR | C27: 12 | D27: 16805 | F27: =60*C27*E27 -> 0 | G27: =D27*E27 -> 0 | H27: =C27*E27 -> 0
A28: 572973 | B28: 500 kVA Padmount XFMR | C28: 12 | D28: 22707 | F28: =60*C28*E28 -> 0 | G28: =D28*E28 -> 0 | H28: =C28*E28 -> 0
A29: 572964 | B29: 750 kVA Padmount XFMR | C29: 12 | D29: 25163 | F29: =60*C29*E29 -> 0 | G29: =D29*E29 -> 0 | H29: =C29*E29 -> 0
A30: 572967 | B30: 1000 kVA Padmount XFMR | C30: 12 | D30: 25151 | F30: =60*C30*E30 -> 0 | G30: =D30*E30 -> 0 | H30: =C30*E30 -> 0
A31: 572971 | B31: 1500 kVA Padmount XFMR | C31: 12 | D31: 37152 | F31: =60*C31*E31 -> 0 | G31: =D31*E31 -> 0 | H31: =C31*E31 -> 0
A32: 572972 | B32: 2000 kVA Padmount XFMR | C32: 12 | D32: 43042 | F32: =60*C32*E32 -> 0 | G32: =D32*E32 -> 0 | H32: =C32*E32 -> 0
A33: 572974 | B33: 2500 kVA Padmount XFMR | C33: 12 | D33: 53097 | F33: =60*C33*E33 -> 0 | G33: =D33*E33 -> 0 | H33: =C33*E33 -> 0
A34: 500179 | B34: 200 Amp Elbows (each) | C34: 2 | D34: 40 | F34: =60*C34*E34 -> 0 | G34: =D34*E34 -> 0 | H34: =C34*E34 -> 0
... A38: 524244 | B38: Primary Metering Cabinet | C38: 12 | D38: 18583 | F38: =60*C38*E38 -> 0 | G38: =D38*E38 -> 0 | H38: =C38*E38 -> 0
B40: Underground Equipment
A42: 573079 | B42: 100 kVA Underground XFMR | C42: 8 | D42: 10280 | F42: =60*C42*E42 -> 0 | G42: =D42*E42 -> 0 | H42: =C42*E42 -> 0
A43: 572936 | B43: 167 kVA Underground XFMR | C43: 8 | D43: 16492 | E43: 0 | F43: =60*C43*E43 -> 0 | G43: =D43*E43 -> 0 | H43: =C43*E43 -> 0
B45: TOTAL MATERIAL COST | C45: =SUM(G6:G43) -> 0
B46: TOTAL LABOR COST | C46: =SUM(F6:F43) -> 0
B47: TOTAL LABOR HOURS | H47: =SUM(H6:H46) -> 0
